Workbook

Sheet How to use
A1: PRISMA tracking sheet
A2: Project | B2: Privacy-Preserving Heart Disease Risk Prediction Using FHE · COMP4101 Practicum · UDST
A3: Goes with | B3: SLR_Protocol_v3 (team roles, criteria I1–I5 and E1–E6)
A5: Colour legend
A6: Yellow cells | B6: Type here. These are the only cells anyone should edit.
A7: Grey cells | B7: Calculated automatically. Do not type over them.
A9: Pairs
A10: Pair 1 | B10: Saif (screener 1) and Naif (screener 2): IEEE Xplore, Set 1, synthesis RQ1 and RQ4
A11: Pair 2 | B11: Sarim (screener 1) and Hassan (screener 2): PubMed, Set 2, synthesis RQ3
A12: Pair 3 | B12: Khalid (screener 1) and Abdullah (screener 2): Scopus, Set 3, synthesis RQ2
A14: Who fills what
A15: Search Log | B15: The first person in each pair types the search row on the day it is run; the partner re-runs it and ticks 'Confirmed by'.
A16: PRISMA Counts | B16: Hassan types 'Duplicate records removed' after RefWorks de-duplication. Everything else on that tab fills itself.
A17: Screening Log | B17: Hassan pastes one row per de-duplicated record and assigns it to Pair 1, 2 or 3 (split evenly, at random). Screener 1 fills column G and screener 2 fills column H, independently. If one says Exclude and the other does not, the row shows 'Pending' and the tie-breaker fills 'Resolved decision' (Naif for Pairs 2 and 3, Abdullah for Pair 1).
A18: Full text | B18: Each pair splits its surviving papers between its two members: put your name in 'Full-text reader'. The partner checks every exclusion.
A19: Snowballing | B19: Papers found in reference lists of included studies: add them with Source = Snowballing. They skip title/abstract screening and go straight to full text.
A21: Rules
A22: Include vs Maybe | B22: If neither screener says Exclude, the record goes to full text automatically. Only Exclude-vs-not disagreements need resolving.
A23: Full text not available | B23: Set 'Full text retrieved?' to No. That is exclusion E5, so leave the decision and code columns empty.
A24: Excluding at full text | B24: Set 'Full-text decision' to Exclude and pick a code (E1, E2, E3, E4 or E6). Every exclusion needs a code.
A25: Checks | B25: The PRISMA Counts tab shows OK or a warning beside each check. Fix warnings before the numbers go into a report.
A27: Example Screening Log row | B27: (format only; do not copy into the log)
A28: Record ID | B28: S-001
A29: Title | B29: Secure logistic regression based on homomorphic encryption: design and evaluation
A30: Authors | B30: Kim M; Song Y; Wang S; Xia Y; Jiang X
A31: Year | B31: 2018
A32: Source | B32: Scopus
A33: Pair | B33: Pair 3
A34: Screener 1 decision | B34: Include
... A36: Agree? | B36: Yes
A37: Resolved decision
A38: Final T/A | B38: Include
A39: Full-text reader | B39: Khalid
A40: Full text retrieved? | B40: Yes
A41: Full-text decision | B41: Include
A42: Exclusion code
A43: Notes | B43: Search-check paper

Sheet PRISMA Counts
A1: PRISMA 2020 flow counts
A2: Labels follow the PRISMA 2020 flow diagram boxes, so each number can be copied straight into the diagram.
A4: Identification (databases)
A5: Records identified: IEEE Xplore | B5: ='Search Log'!H2 -> 337 | C5: From Search Log
A6: Records identified: PubMed | B6: ='Search Log'!H3 -> 172 | C6: From Search Log
A7: Records identified: Scopus | B7: ='Search Log'!H4 -> 1017 | C7: From Search Log
A8: Records identified: total | B8: =SUM(B5:B7) -> 1526
A9: Duplicate records removed | C9: Hassan types this after RefWorks de-duplication
A10: Records to screen (total minus duplicates) | B10: =B8-B9 -> 1526
A11: Screening (databases)
A12: Records screened (rows in Screening Log) | B12: =COUNTIFS('Screening Log'!$A$2:$A$801,"<>",'Screening Log'!$E$2:$E$801,"<>Snowballing") -> 0 | C12: Should equal records to screen, see checks
A13: Records excluded at title/abstract | B13: =COUNTIFS('Screening Log'!$A$2:$A$801,"<>",'Screening Log'!$E$2:$E$801,"<>Snowballing",'Screening Log'!$K$2:$K$801,"Exclude") -> 0 | C13: Uses the final T/A decision
A14: Title/abstract decisions not final yet | B14: =B12-B13-B15 -> 0 | C14: Waiting for a screener, or Pending a tie-break
A15: Reports sought for retrieval | B15: =COUNTIFS('Screening Log'!$A$2:$A$801,"<>",'Screening Log'!$E$2:$E$801,"<>Snowballing",'Screening Log'!$K$2:$K$801,"Include")+COUNTIFS('Screening Log'!$A$2:$A$801,"<>",'Screening Log'!$E$2:$E$801,"<>Snowballing",'Screening Log'!$K$2:$K$801,"Maybe") -> 0 | C15: Include + Maybe go to full text
A16: Reports not retrieved (E5) | B16: =COUNTIFS('Screening Log'!$A$2:$A$801,"<>",'Screening Log'!$E$2:$E$801,"<>Snowballing",'Screening Log'!$M$2:$M$801,"No") -> 0
A17: Reports assessed for eligibility | B17: =B15-B16 -> 0
A18: Reports excluded: E1 other privacy technique only | B18: =COUNTIFS('Screening Log'!$A$2:$A$801,"<>",'Screening Log'!$E$2:$E$801,"<>Snowballing",'Screening Log'!$N$2:$N$801,"Exclude",'Screening Log'!$O$2:$O$801,"E1") -> 0
A19: Reports excluded: E2 not health data | B19: =COUNTIFS('Screening Log'!$A$2:$A$801,"<>",'Screening Log'!$E$2:$E$801,"<>Snowballing",'Screening Log'!$N$2:$N$801,"Exclude",'Screening Log'!$O$2:$O$801,"E2") -> 0
A20: Reports excluded: E3 purely theoretical | B20: =COUNTIFS('Screening Log'!$A$2:$A$801,"<>",'Screening Log'!$E$2:$E$801,"<>Snowballing",'Screening Log'!$N$2:$N$801,"Exclude",'Screening Log'!$O$2:$O$801,"E3") -> 0
A21: Reports excluded: E4 survey, review, thesis, etc. | B21: =COUNTIFS('Screening Log'!$A$2:$A$801,"<>",'Screening Log'!$E$2:$E$801,"<>Snowballing",'Screening Log'!$N$2:$N$801,"Exclude",'Screening Log'!$O$2:$O$801,"E4") -> 0
A22: Reports excluded: E6 duplicate or earlier version | B22: =COUNTIFS('Screening Log'!$A$2:$A$801,"<>",'Screening Log'!$E$2:$E$801,"<>Snowballing",'Screening Log'!$N$2:$N$801,"Exclude",'Screening Log'!$O$2:$O$801,"E6") -> 0
A23: Reports excluded at full text: total | B23: =SUM(B18:B22) -> 0
A24: Studies included from databases | B24: =COUNTIFS('Screening Log'!$A$2:$A$801,"<>",'Screening Log'!$E$2:$E$801,"<>Snowballing",'Screening Log'!$N$2:$N$801,"Include") -> 0
A25: Full-text decisions still pending | B25: =B17-B23-B24 -> 0 | C25: Not decided yet, or excluded without a code
A26: Other methods (backward snowballing)
A27: Records identified from reference lists | B27: =COUNTIFS('Screening Log'!$A$2:$A$801,"<>",'Screening Log'!$E$2:$E$801,"Snowballing") -> 0 | C27: Source = Snowballing
A28: Reports not retrieved | B28: =COUNTIFS('Screening Log'!$A$2:$A$801,"<>",'Screening Log'!$E$2:$E$801,"Snowballing",'Screening Log'!$M$2:$M$801,"No") -> 0
A29: Reports assessed for eligibility | B29: =B27-B28 -> 0
A30: Reports excluded | B30: =COUNTIFS('Screening Log'!$A$2:$A$801,"<>",'Screening Log'!$E$2:$E$801,"Snowballing",'Screening Log'!$N$2:$N$801,"Exclude") -> 0 | C30: Reasons are in the Screening Log
A31: Studies included from snowballing | B31: =COUNTIFS('Screening Log'!$A$2:$A$801,"<>",'Screening Log'!$E$2:$E$801,"Snowballing",'Screening Log'!$N$2:$N$801,"Include") -> 0
A32: Included
A33: Total studies included in review | B33: =B24+B31 -> 0 | C33: This is the number your synthesis is based on
A34: Screening agreement (title/abstract, both screeners)
A35: Records with both decisions | B35: =COUNTIFS('Screening Log'!$A$2:$A$801,"<>",'Screening Log'!$E$2:$E$801,"<>Snowballing",'Screening Log'!$G$2:$G$801,"<>",'Screening Log'!$H$2:$H$801,"<>") -> 0
A36: Agreements (same decision) | B36: =COUNTIFS('Screening Log'!$I$2:$I$801,"Yes") -> 0
A37: Percent agreement | B37: =IF(B35=0,0,B36/B35) -> 0 | C37: Report this in the method section
A38: Disagreements settled by tie-breaker | B38: =COUNTIFS('Screening Log'!$K$2:$K$801,"<>Pending",'Screening Log'!$G$2:$G$801,"Exclude",'Screening Log'!$H$2:$H$801,"<>Exclude",'Screening Log'!$H$2:$H$801,"<>")+COUNTIFS('Screening Log'!$K$2:$K$801,"<>Pending",'Screening Log'!$H$2:$H$801,"Exclude",'Screening Log'!$G$2:$G$801,"<>Exclude",'Screening Log'!$G$2:$G$801,"<>") -> 0
A39: Workload
A40: Pair 1 (Saif, Naif): records in set | B40: =COUNTIFS('Screening Log'!$A$2:$A$801,"<>",'Screening Log'!$E$2:$E$801,"<>Snowballing",'Screening Log'!$F$2:$F$801,"Pair 1") -> 0
A41: Pair 2 (Sarim, Hassan): records in set | B41: =COUNTIFS('Screening Log'!$A$2:$A$801,"<>",'Screening Log'!$E$2:$E$801,"<>Snowballing",'Screening Log'!$F$2:$F$801,"Pair 2") -> 0
...

Sheet Lists
A1: Exclusion code | B1: Meaning (from protocol) | D1: Sources | E1: People | F1: Pair | G1: Screener 1 | H1: Screener 2 | I1: Database | J1: Synthesis
A2: E1 | B2: Other privacy technique only, no homomorphic encryption (hybrids with HE are kept) | D2: IEEE Xplore | E2: Saif | F2: Pair 1 | G2: Saif | H2: Naif | I2: IEEE Xplore | J2: RQ1, RQ4
A3: E2 | B3: Not applied to health data | D3: PubMed | E3: Naif | F3: Pair 2 | G3: Sarim | H3: Hassan | I3: PubMed | J3: RQ3
A4: E3 | B4: Purely theoretical, no implementation or results | D4: Scopus | E4: Sarim | F4: Pair 3 | G4: Khalid | H4: Abdullah | I4: Scopus | J4: RQ2
A5: E4 | B5: Survey, review, editorial, poster abstract, or thesis | D5: Snowballing | E5: Hassan
A6: E5 | B6: Full text not available through UDST library (use 'Full text retrieved?' = No) | E6: Khalid
A7: E6 | B7: Duplicate or earlier version of an included study | E7: Abdullah

Sheet Search Log
A1: Database | B1: Pair | C1: Run by | D1: Confirmed by | E1: Date run | F1: Exact string used | G1: Filters applied | H1: Results | I1: Notes / changes
A2: IEEE Xplore | B2: Pair 1 | C2: Saif | D2: Naif | E2: 46305 | F2: ("Abstract":"homomorphic encryption" OR "Abstract":"fully homomorphic" OR "Abstract":FHE OR "Abstract":CKKS OR "Abstract":BFV OR "Abstract":BGV OR "Abstract":TenSEAL OR "Abstract":"Microsoft SEAL") AND ("Abstract":"machine learning" OR "Abstract":"logistic regression" OR "Abstract":"neural network" OR "Abstract":"deep learning" OR "Abstract":classif* OR "Abstract":predict* OR "Abstract":inference) AND ("Abstract":health* OR "Abstract":medical OR "Abstract":clinical OR "Abstract":patient* OR "Abstract":disease* OR "Abstract":biomedical OR "Abstract":diagnos* OR "Abstract":genom* OR "Abstract":cancer OR "Abstract":diabet* OR "Abstract":"heart disease" OR "Abstract":cardiovascular) | G2: Publication Year 2016–2026; Conferences and Journals | H2: 337 | I2: Exported in 4 RIS files (100 + 100 + 100 + 37): research/slr/exports/IEEE_2026-10-10_p1–p4.ris
A3: PubMed | B3: Pair 2 | C3: Sarim | D3: Hassan | E3: 46305 | F3: ("homomorphic encryption"[tiab] OR "fully homomorphic"[tiab] OR FHE[tiab] OR CKKS[tiab] OR BFV[tiab] OR BGV[tiab] OR TenSEAL[tiab] OR "Microsoft SEAL"[tiab]) AND ("machine learning"[tiab] OR "logistic regression"[tiab] OR "neural network"[tiab] OR "deep learning"[tiab] OR classif*[tiab] OR predict*[tiab] OR inference[tiab]) AND (health*[tiab] OR medical[tiab] OR biomedical[tiab] OR clinical[tiab] OR patient*[tiab] OR disease*[tiab] OR diagnos*[tiab] OR genom*[tiab] OR cancer[tiab] OR diabet*[tiab] OR "heart disease"[tiab] OR cardiovascular[tiab]) AND 2016:2026[dp] AND english[la] | G3: In the string: 2016:2026[dp], english[la] | H3: 172 | I3: Replaces ACM Digital Library (no UDST subscription; filters and export locked). A [tw] variant (176 results) was tested and not used. Export: research/slr/exports/PubMed_2026-10-10.nbib
A4: Scopus | B4: Pair 3 | C4: Khalid | D4: Abdullah | E4: 46305 | F4: TITLE-ABS-KEY ( "homomorphic encryption" OR "fully homomorphic" OR fhe OR ckks OR bfv OR bgv OR tenseal OR "Microsoft SEAL" ) AND TITLE-ABS-KEY ( "machine learning" OR "logistic regression" OR "neural network" OR "deep learning" OR classif* OR predict* OR inference ) AND TITLE-ABS-KEY ( health* OR medical OR biomedical OR clinical OR patient* OR disease* OR diagnos* OR genom* OR cancer OR diabet* OR "heart disease" OR cardiovascular ) AND PUBYEAR > 2015 AND PUBYEAR < 2027 AND LANGUAGE ( english ) AND ( DOCTYPE ( ar ) OR DOCTYPE ( cp ) ) | G4: In the string: PUBYEAR 2016–2026, English, DOCTYPE ar + cp | H4: 1017 | I4: Over the 400 limit. Narrowing was tested (766 and 855 results, still over), so the full 1,017 was kept by team decision. Export: research/slr/exports/Scopus_2026-10-10.ris
A5: Total identified | H5: =SUM(H2:H4) -> 1526

Sheet Screening Log
A1: Record ID | B1: Title | C1: Authors | D1: Year | E1: Source | F1: Pair | G1: Screener 1 decision | H1: Screener 2 decision | I1: Agree? | J1: Resolved decision | K1: Final T/A | L1: Full-text reader | M1: Full text retrieved? | N1: Full-text decision | O1: Exclusion code | P1: Notes
I2: =IF(OR(G2="",H2=""),"",IF(G2=H2,"Yes","No")) | K2: =IF(E2="Snowballing","n/a",IF(AND(G2="",H2=""),"",IF(OR(G2="",H2=""),"Waiting",IF(G2=H2,G2,IF(AND(G2<>"Exclude",H2<>"Exclude"),"Maybe",IF(J2<>"",J2,"Pending"))))))
I3: =IF(OR(G3="",H3=""),"",IF(G3=H3,"Yes","No")) | K3: =IF(E3="Snowballing","n/a",IF(AND(G3="",H3=""),"",IF(OR(G3="",H3=""),"Waiting",IF(G3=H3,G3,IF(AND(G3<>"Exclude",H3<>"Exclude"),"Maybe",IF(J3<>"",J3,"Pending"))))))
I4: =IF(OR(G4="",H4=""),"",IF(G4=H4,"Yes","No")) | K4: =IF(E4="Snowballing","n/a",IF(AND(G4="",H4=""),"",IF(OR(G4="",H4=""),"Waiting",IF(G4=H4,G4,IF(AND(G4<>"Exclude",H4<>"Exclude"),"Maybe",IF(J4<>"",J4,"Pending"))))))
I5: =IF(OR(G5="",H5=""),"",IF(G5=H5,"Yes","No")) | K5: =IF(E5="Snowballing","n/a",IF(AND(G5="",H5=""),"",IF(OR(G5="",H5=""),"Waiting",IF(G5=H5,G5,IF(AND(G5<>"Exclude",H5<>"Exclude"),"Maybe",IF(J5<>"",J5,"Pending"))))))
I6: =IF(OR(G6="",H6=""),"",IF(G6=H6,"Yes","No")) | K6: =IF(E6="Snowballing","n/a",IF(AND(G6="",H6=""),"",IF(OR(G6="",H6=""),"Waiting",IF(G6=H6,G6,IF(AND(G6<>"Exclude",H6<>"Exclude"),"Maybe",IF(J6<>"",J6,"Pending"))))))
I7: =IF(OR(G7="",H7=""),"",IF(G7=H7,"Yes","No")) | K7: =IF(E7="Snowballing","n/a",IF(AND(G7="",H7=""),"",IF(OR(G7="",H7=""),"Waiting",IF(G7=H7,G7,IF(AND(G7<>"Exclude",H7<>"Exclude"),"Maybe",IF(J7<>"",J7,"Pending"))))))
I8: =IF(OR(G8="",H8=""),"",IF(G8=H8,"Yes","No")) | K8: =IF(E8="Snowballing","n/a",IF(AND(G8="",H8=""),"",IF(OR(G8="",H8=""),"Waiting",IF(G8=H8,G8,IF(AND(G8<>"Exclude",H8<>"Exclude"),"Maybe",IF(J8<>"",J8,"Pending"))))))
I9: =IF(OR(G9="",H9=""),"",IF(G9=H9,"Yes","No")) | K9: =IF(E9="Snowballing","n/a",IF(AND(G9="",H9=""),"",IF(OR(G9="",H9=""),"Waiting",IF(G9=H9,G9,IF(AND(G9<>"Exclude",H9<>"Exclude"),"Maybe",IF(J9<>"",J9,"Pending"))))))
I10: =IF(OR(G10="",H10=""),"",IF(G10=H10,"Yes","No")) | K10: =IF(E10="Snowballing","n/a",IF(AND(G10="",H10=""),"",IF(OR(G10="",H10=""),"Waiting",IF(G10=H10,G10,IF(AND(G10<>"Exclude",H10<>"Exclude"),"Maybe",IF(J10<>"",J10,"Pending"))))))
I11: =IF(OR(G11="",H11=""),"",IF(G11=H11,"Yes","No")) | K11: =IF(E11="Snowballing","n/a",IF(AND(G11="",H11=""),"",IF(OR(G11="",H11=""),"Waiting",IF(G11=H11,G11,IF(AND(G11<>"Exclude",H11<>"Exclude"),"Maybe",IF(J11<>"",J11,"Pending"))))))
I12: =IF(OR(G12="",H12=""),"",IF(G12=H12,"Yes","No")) | K12: =IF(E12="Snowballing","n/a",IF(AND(G12="",H12=""),"",IF(OR(G12="",H12=""),"Waiting",IF(G12=H12,G12,IF(AND(G12<>"Exclude",H12<>"Exclude"),"Maybe",IF(J12<>"",J12,"Pending"))))))
I13: =IF(OR(G13="",H13=""),"",IF(G13=H13,"Yes","No")) | K13: =IF(E13="Snowballing","n/a",IF(AND(G13="",H13=""),"",IF(OR(G13="",H13=""),"Waiting",IF(G13=H13,G13,IF(AND(G13<>"Exclude",H13<>"Exclude"),"Maybe",IF(J13<>"",J13,"Pending"))))))
... I801: =IF(OR(G801="",H801=""),"",IF(G801=H801,"Yes","No")) | K801: =IF(E801="Snowballing","n/a",IF(AND(G801="",H801=""),"",IF(OR(G801="",H801=""),"Waiting",IF(G801=H801,G801,IF(AND(G801<>"Exclude",H801<>"Exclude"),"Maybe",IF(J801<>"",J801,"Pending"))))))
